{"name": "# C5151 Verify if the Device online card shows the proper number of devices", "status": "broken", "statusDetails": {"message": "selenium.common.exceptions.TimeoutException: Message: \n\n", "trace": "  File \"c:\\users\\rapid\\appdata\\local\\programs\\python\\python38-32\\lib\\site-packages\\behave\\model.py\", line 1329, in run\n    match.run(runner.context)\n  File \"c:\\users\\rapid\\appdata\\local\\programs\\python\\python38-32\\lib\\site-packages\\behave\\matchers.py\", line 98, in run\n    self.func(context, *args, **kwargs)\n  File \"features\\steps\\C5151_Verify_if_the_Device_online_card_shows_the_proper_number_of_devices.py\", line 8, in vrf_qntty_is_the_same\n    context.app.main_page.vrf_qntty_is_the_same()\n  File \"C:\\Everything\\IT\\Testing\\Automation_08_09_2019\\UIautomation_python\\pages\\main_page.py\", line 509, in vrf_qntty_is_the_same\n    no_data_available = wait.until(EC.element_to_be_clickable(NO_DATA)).text\n  File \"c:\\users\\rapid\\appdata\\local\\programs\\python\\python38-32\\lib\\site-packages\\selenium\\webdriver\\support\\wait.py\", line 80, in until\n    raise TimeoutException(message, screen, stacktrace)\n"}, "steps": [{"name": "Given Loginpage", "status": "passed", "start": 1600826545750, "stop": 1600826548494}, {"name": "Then Login with the given credentials", "status": "passed", "start": 1600826548495, "stop": 1600826553390}, {"name": "Then Verify if the number of devices on the DEVICE ONLINE card should match the number of devices with online status on the Devices page", "status": "broken", "statusDetails": {"message": "selenium.common.exceptions.TimeoutException: Message: \n\n", "trace": "  File \"c:\\users\\rapid\\appdata\\local\\programs\\python\\python38-32\\lib\\site-packages\\behave\\model.py\", line 1329, in run\n    match.run(runner.context)\n  File \"c:\\users\\rapid\\appdata\\local\\programs\\python\\python38-32\\lib\\site-packages\\behave\\matchers.py\", line 98, in run\n    self.func(context, *args, **kwargs)\n  File \"features\\steps\\C5151_Verify_if_the_Device_online_card_shows_the_proper_number_of_devices.py\", line 8, in vrf_qntty_is_the_same\n    context.app.main_page.vrf_qntty_is_the_same()\n  File \"C:\\Everything\\IT\\Testing\\Automation_08_09_2019\\UIautomation_python\\pages\\main_page.py\", line 509, in vrf_qntty_is_the_same\n    no_data_available = wait.until(EC.element_to_be_clickable(NO_DATA)).text\n  File \"c:\\users\\rapid\\appdata\\local\\programs\\python\\python38-32\\lib\\site-packages\\selenium\\webdriver\\support\\wait.py\", line 80, in until\n    raise TimeoutException(message, screen, stacktrace)\n"}, "start": 1600826553390, "stop": 1600826574199}], "start": 1600826540460, "stop": 1600826576327, "uuid": "013d29f8-028c-4864-9d62-861c2386441b", "historyId": "5cc4315b0274f8ba338074930173b790", "labels": [{"name": "severity", "value": "normal"}, {"name": "feature", "value": "# C5151 Verify if the Device online card shows the proper number of devices"}, {"name": "framework", "value": "behave"}, {"name": "language", "value": "cpython3"}]}