{"name": "# C5162 Signal Strength section", "status": "broken", "statusDetails": {"message": "selenium.common.exceptions.TimeoutException: Message: \n\n", "trace": "  File \"c:\\users\\rapid\\appdata\\local\\programs\\python\\python38-32\\lib\\site-packages\\behave\\model.py\", line 1329, in run\n    match.run(runner.context)\n  File \"c:\\users\\rapid\\appdata\\local\\programs\\python\\python38-32\\lib\\site-packages\\behave\\matchers.py\", line 98, in run\n    self.func(context, *args, **kwargs)\n  File \"features\\steps\\C5162_Signal_Strength_section.py\", line 24, in inscrptn_no_dt_avlbl_in_sgnl_strngt\n    context.app.main_page.inscrptn_no_dt_avlbl_in_sgnl_strngt(inscrptn_no_dt_avlbl_in_sgnl_strngt)\n  File \"C:\\Everything\\IT\\Testing\\Automation_08_09_2019\\UIautomation_python\\pages\\main_page.py\", line 941, in inscrptn_no_dt_avlbl_in_sgnl_strngt\n    no_dt_in_grps_blck = wait.until(EC.visibility_of_element_located(NO_DT_IN_SGNL_STRNGT_SCTN)).text\n  File \"c:\\users\\rapid\\appdata\\local\\programs\\python\\python38-32\\lib\\site-packages\\selenium\\webdriver\\support\\wait.py\", line 80, in until\n    raise TimeoutException(message, screen, stacktrace)\n"}, "steps": [{"name": "Given Loginpage", "status": "passed", "start": 1602977115195, "stop": 1602977117964}, {"name": "Then Login with the given credentials", "status": "passed", "start": 1602977117964, "stop": 1602977120823}, {"name": "Then Click Dashboard menu icon and make sure Dashboard page reloaded", "status": "passed", "start": 1602977120824, "stop": 1602977121012}, {"name": "And Make sure Signal Strength is on the screen", "status": "passed", "start": 1602977121012, "stop": 1602977121068}, {"name": "Then Mouse hover question mark in top right of the Signal Strength block and make sure tooltip appears", "status": "passed", "start": 1602977121068, "stop": 1602977121672}, {"name": "Then The inscription No Data Available is in the center of Signal Strength block", "status": "broken", "statusDetails": {"message": "selenium.common.exceptions.TimeoutException: Message: \n\n", "trace": "  File \"c:\\users\\rapid\\appdata\\local\\programs\\python\\python38-32\\lib\\site-packages\\behave\\model.py\", line 1329, in run\n    match.run(runner.context)\n  File \"c:\\users\\rapid\\appdata\\local\\programs\\python\\python38-32\\lib\\site-packages\\behave\\matchers.py\", line 98, in run\n    self.func(context, *args, **kwargs)\n  File \"features\\steps\\C5162_Signal_Strength_section.py\", line 24, in inscrptn_no_dt_avlbl_in_sgnl_strngt\n    context.app.main_page.inscrptn_no_dt_avlbl_in_sgnl_strngt(inscrptn_no_dt_avlbl_in_sgnl_strngt)\n  File \"C:\\Everything\\IT\\Testing\\Automation_08_09_2019\\UIautomation_python\\pages\\main_page.py\", line 941, in inscrptn_no_dt_avlbl_in_sgnl_strngt\n    no_dt_in_grps_blck = wait.until(EC.visibility_of_element_located(NO_DT_IN_SGNL_STRNGT_SCTN)).text\n  File \"c:\\users\\rapid\\appdata\\local\\programs\\python\\python38-32\\lib\\site-packages\\selenium\\webdriver\\support\\wait.py\", line 80, in until\n    raise TimeoutException(message, screen, stacktrace)\n"}, "start": 1602977121672, "stop": 1602977139890}], "start": 1602977109910, "stop": 1602977142001, "uuid": "30bb209d-b99a-40b5-aeb1-66f9c1f961cb", "historyId": "5eaa07d92f5cb375ab7fe2d916367e55", "labels": [{"name": "severity", "value": "normal"}, {"name": "feature", "value": "# C5162 Signal Strength section"}, {"name": "framework", "value": "behave"}, {"name": "language", "value": "cpython3"}]}